<?xml version="1.0" ?>
<!-- Generated using onshape-to-robot -->
<!-- Onshape https://cad.onshape.com/documents/6d2de7d00083ca907fc2babe/w/304502f29ec410dd09729b69/e/5f48c3461118a81a0306302b -->
<robot name="arachne">
  <!-- Link lowerbody -->
  <link name="lowerbody">
    <inertial>
      <origin xyz="-0.0384676 -0.0406717 0.0095234" rpy="0 0 0"/>
      <mass value="1.10838"/>
      <inertia ixx="0.0056755" ixy="6.08941e-06" ixz="7.69729e-07" iyy="0.00403706" iyz="0.000516495" izz="0.00802109"/>
    </inertial>
    <!-- Part shell -->
    <visual>
      <origin xyz="-0.542935 -0.0510306 0.0135385" rpy="-1.09062e-14 -1.58122e-14 -1.35413e-26"/>
      <geometry>
        <mesh filename="package://assets/shell.stl"/>
      </geometry>
      <material name="shell_material">
        <color rgba="0.25 0.25 0.25 1"/>
      </material>
    </visual>
    <collision>
      <origin xyz="-0.542935 -0.0510306 0.0135385" rpy="-1.09062e-14 -1.58122e-14 -1.35413e-26"/>
      <geometry>
        <mesh filename="package://assets/shell.stl"/>
      </geometry>
    </collision>
    <!-- Part lowerbody -->
    <visual>
      <origin xyz="-0.0383733 0.0113195 -0.0407615" rpy="1.09062e-14 1.58122e-14 -3.14159"/>
      <geometry>
        <mesh filename="package://assets/lowerbody.stl"/>
      </geometry>
      <material name="lowerbody_material">
        <color rgba="0.25 0.25 0.25 1"/>
      </material>
    </visual>
    <collision>
      <origin xyz="-0.0383733 0.0113195 -0.0407615" rpy="1.09062e-14 1.58122e-14 -3.14159"/>
      <geometry>
        <mesh filename="package://assets/lowerbody.stl"/>
      </geometry>
    </collision>
    <!-- Part upperbody -->
    <visual>
      <origin xyz="-0.301202 -0.0470153 0.00753852" rpy="-1.09062e-14 -1.58122e-14 -1.35413e-26"/>
      <geometry>
        <mesh filename="package://assets/upperbody.stl"/>
      </geometry>
      <material name="upperbody_material">
        <color rgba="0.25 0.25 0.25 1"/>
      </material>
    </visual>
    <collision>
      <origin xyz="-0.301202 -0.0470153 0.00753852" rpy="-1.09062e-14 -1.58122e-14 -1.35413e-26"/>
      <geometry>
        <mesh filename="package://assets/upperbody.stl"/>
      </geometry>
    </collision>
    <!-- Part mask -->
    <visual>
      <origin xyz="-0.18804 -0.144066 0.0520093" rpy="-1.5708 1.57489e-14 -3.14159"/>
      <geometry>
        <mesh filename="package://assets/mask.stl"/>
      </geometry>
      <material name="mask_material">
        <color rgba="0.25 0.25 0.25 1"/>
      </material>
    </visual>
    <collision>
      <origin xyz="-0.18804 -0.144066 0.0520093" rpy="-1.5708 1.57489e-14 -3.14159"/>
      <geometry>
        <mesh filename="package://assets/mask.stl"/>
      </geometry>
    </collision>
    <!-- Part neck -->
    <visual>
      <origin xyz="0.206227 -0.124066 0.0509436" rpy="1.5708 -1.57489e-14 -1.35413e-26"/>
      <geometry>
        <mesh filename="package://assets/neck.stl"/>
      </geometry>
      <material name="neck_material">
        <color rgba="0.25 0.25 0.25 1"/>
      </material>
    </visual>
    <collision>
      <origin xyz="0.206227 -0.124066 0.0509436" rpy="1.5708 -1.57489e-14 -1.35413e-26"/>
      <geometry>
        <mesh filename="package://assets/neck.stl"/>
      </geometry>
    </collision>
    <!-- Part idler -->
    <visual>
      <origin xyz="0.062236 0.0615842 0.20775" rpy="-3.14159 9.72151e-15 -2.70526"/>
      <geometry>
        <mesh filename="package://assets/idler.stl"/>
      </geometry>
      <material name="idler_material">
        <color rgba="0.25 0.25 0.25 1"/>
      </material>
    </visual>
    <collision>
      <origin xyz="0.062236 0.0615842 0.20775" rpy="-3.14159 9.72151e-15 -2.70526"/>
      <geometry>
        <mesh filename="package://assets/idler.stl"/>
      </geometry>
    </collision>
    <!-- Part part_1 -->
    <visual>
      <origin xyz="-0.0383733 -0.0275379 -0.0320315" rpy="-1.58122e-14 1.09062e-14 1.5708"/>
      <geometry>
        <mesh filename="package://assets/part_1.stl"/>
      </geometry>
      <material name="part_1_material">
        <color rgba="0.25 0.25 0.25 1"/>
      </material>
    </visual>
    <collision>
      <origin xyz="-0.0383733 -0.0275379 -0.0320315" rpy="-1.58122e-14 1.09062e-14 1.5708"/>
      <geometry>
        <mesh filename="package://assets/part_1.stl"/>
      </geometry>
    </collision>
    <!-- Part idler_2 -->
    <visual>
      <origin xyz="-0.141584 -0.0100689 0.20775" rpy="3.14159 -1.58122e-14 -1.35416e-26"/>
      <geometry>
        <mesh filename="package://assets/idler.stl"/>
      </geometry>
      <material name="idler_2_material">
        <color rgba="0.25 0.25 0.25 1"/>
      </material>
    </visual>
    <collision>
      <origin xyz="-0.141584 -0.0100689 0.20775" rpy="3.14159 -1.58122e-14 -1.35416e-26"/>
      <geometry>
        <mesh filename="package://assets/idler.stl"/>
      </geometry>
    </collision>
    <!-- Part idler_3 -->
    <visual>
      <origin xyz="-0.130412 0.0799642 0.20775" rpy="3.14159 -1.89398e-14 -0.436332"/>
      <geometry>
        <mesh filename="package://assets/idler.stl"/>
      </geometry>
      <material name="idler_3_material">
        <color rgba="0.25 0.25 0.25 1"/>
      </material>
    </visual>
    <collision>
      <origin xyz="-0.130412 0.0799642 0.20775" rpy="3.14159 -1.89398e-14 -0.436332"/>
      <geometry>
        <mesh filename="package://assets/idler.stl"/>
      </geometry>
    </collision>
    <!-- Part idler_4 -->
    <visual>
      <origin xyz="0.0541364 -0.133587 0.20775" rpy="3.14159 1.91554e-14 2.46337"/>
      <geometry>
        <mesh filename="package://assets/idler.stl"/>
      </geometry>
      <material name="idler_4_material">
        <color rgba="0.25 0.25 0.25 1"/>
      </material>
    </visual>
    <collision>
      <origin xyz="0.0541364 -0.133587 0.20775" rpy="3.14159 1.91554e-14 2.46337"/>
      <geometry>
        <mesh filename="package://assets/idler.stl"/>
      </geometry>
    </collision>
    <!-- Part idler_5 -->
    <visual>
      <origin xyz="0.0648374 -0.030349 0.20775" rpy="-3.14159 1.58122e-14 -3.14159"/>
      <geometry>
        <mesh filename="package://assets/idler.stl"/>
      </geometry>
      <material name="idler_5_material">
        <color rgba="0.25 0.25 0.25 1"/>
      </material>
    </visual>
    <collision>
      <origin xyz="0.0648374 -0.030349 0.20775" rpy="-3.14159 1.58122e-14 -3.14159"/>
      <geometry>
        <mesh filename="package://assets/idler.stl"/>
      </geometry>
    </collision>
    <!-- Part idler_6 -->
    <visual>
      <origin xyz="-0.143607 -0.117795 0.20775" rpy="3.14159 -5.47011e-15 0.678221"/>
      <geometry>
        <mesh filename="package://assets/idler.stl"/>
      </geometry>
      <material name="idler_6_material">
        <color rgba="0.25 0.25 0.25 1"/>
      </material>
    </visual>
    <collision>
      <origin xyz="-0.143607 -0.117795 0.20775" rpy="3.14159 -5.47011e-15 0.678221"/>
      <geometry>
        <mesh filename="package://assets/idler.stl"/>
      </geometry>
    </collision>
    <!-- Part e07_mg996r -->
    <visual>
      <origin xyz="0.039448 0.0621463 0.0135385" rpy="1.65669e-14 9.72151e-15 -2.70526"/>
      <geometry>
        <mesh filename="package://assets/e07_mg996r.stl"/>
      </geometry>
      <material name="e07_mg996r_material">
        <color rgba="0.25 0.25 0.25 1"/>
      </material>
    </visual>
    <collision>
      <origin xyz="0.039448 0.0621463 0.0135385" rpy="1.65669e-14 9.72151e-15 -2.70526"/>
      <geometry>
        <mesh filename="package://assets/e07_mg996r.stl"/>
      </geometry>
    </collision>
    <!-- Part servo_horns -->
    <visual>
      <origin xyz="0.0485111 0.0663725 0.0307885" rpy="-1.5708 -2.57421e-15 -2.70526"/>
      <geometry>
        <mesh filename="package://assets/servo_horns.stl"/>
      </geometry>
      <material name="servo_horns_material">
        <color rgba="0.25 0.25 0.25 1"/>
      </material>
    </visual>
    <collision>
      <origin xyz="0.0485111 0.0663725 0.0307885" rpy="-1.5708 -2.57421e-15 -2.70526"/>
      <geometry>
        <mesh filename="package://assets/servo_horns.stl"/>
      </geometry>
    </collision>
    <!-- Part e07_mg996r_2 -->
    <visual>
      <origin xyz="-0.121169 -0.0202089 0.0135385" rpy="-1.09062e-14 -1.58122e-14 -1.35416e-26"/>
      <geometry>
        <mesh filename="package://assets/e07_mg996r.stl"/>
      </geometry>
      <material name="e07_mg996r_2_material">
        <color rgba="0.25 0.25 0.25 1"/>
      </material>
    </visual>
    <collision>
      <origin xyz="-0.121169 -0.0202089 0.0135385" rpy="-1.09062e-14 -1.58122e-14 -1.35416e-26"/>
      <geometry>
        <mesh filename="package://assets/e07_mg996r.stl"/>
      </geometry>
    </collision>
    <!-- Part servo_horns_2 -->
    <visual>
      <origin xyz="-0.131169 -0.0202089 0.0307885" rpy="-1.5708 -1.75355e-16 -4.49293e-15"/>
      <geometry>
        <mesh filename="package://assets/servo_horns.stl"/>
      </geometry>
      <material name="servo_horns_2_material">
        <color rgba="0.25 0.25 0.25 1"/>
      </material>
    </visual>
    <collision>
      <origin xyz="-0.131169 -0.0202089 0.0307885" rpy="-1.5708 -1.75355e-16 -4.49293e-15"/>
      <geometry>
        <mesh filename="package://assets/servo_horns.stl"/>
      </geometry>
    </collision>
    <!-- Part e07_mg996r_3 -->
    <visual>
      <origin xyz="-0.116195 0.0621463 0.0135385" rpy="-3.20189e-15 -1.89398e-14 -0.436332"/>
      <geometry>
        <mesh filename="package://assets/e07_mg996r.stl"/>
      </geometry>
      <material name="e07_mg996r_3_material">
        <color rgba="0.25 0.25 0.25 1"/>
      </material>
    </visual>
    <collision>
      <origin xyz="-0.116195 0.0621463 0.0135385" rpy="-3.20189e-15 -1.89398e-14 -0.436332"/>
      <geometry>
        <mesh filename="package://assets/e07_mg996r.stl"/>
      </geometry>
    </collision>
    <!-- Part servo_horns_3 -->
    <visual>
      <origin xyz="-0.125258 0.0663725 0.0307885" rpy="-1.5708 3.08664e-15 -0.436332"/>
      <geometry>
        <mesh filename="package://assets/servo_horns.stl"/>
      </geometry>
      <material name="servo_horns_3_material">
        <color rgba="0.25 0.25 0.25 1"/>
      </material>
    </visual>
    <collision>
      <origin xyz="-0.125258 0.0663725 0.0307885" rpy="-1.5708 3.08664e-15 -0.436332"/>
      <geometry>
        <mesh filename="package://assets/servo_horns.stl"/>
      </geometry>
    </collision>
    <!-- Part e07_mg996r_4 -->
    <visual>
      <origin xyz="0.044601 -0.112882 0.0135385" rpy="-1.42811e-15 1.91554e-14 2.46337"/>
      <geometry>
        <mesh filename="package://assets/e07_mg996r.stl"/>
      </geometry>
      <material name="e07_mg996r_4_material">
        <color rgba="0.25 0.25 0.25 1"/>
      </material>
    </visual>
    <collision>
      <origin xyz="0.044601 -0.112882 0.0135385" rpy="-1.42811e-15 1.91554e-14 2.46337"/>
      <geometry>
        <mesh filename="package://assets/e07_mg996r.stl"/>
      </geometry>
    </collision>
    <!-- Part servo_horns_4 -->
    <visual>
      <origin xyz="0.052388 -0.119156 0.0307885" rpy="-1.5708 9.93205e-15 2.46337"/>
      <geometry>
        <mesh filename="package://assets/servo_horns.stl"/>
      </geometry>
      <material name="servo_horns_4_material">
        <color rgba="0.25 0.25 0.25 1"/>
      </material>
    </visual>
    <collision>
      <origin xyz="0.052388 -0.119156 0.0307885" rpy="-1.5708 9.93205e-15 2.46337"/>
      <geometry>
        <mesh filename="package://assets/servo_horns.stl"/>
      </geometry>
    </collision>
    <!-- Part e07_mg996r_5 -->
    <visual>
      <origin xyz="0.044422 -0.0202089 0.0135385" rpy="1.09062e-14 1.58122e-14 -3.14159"/>
      <geometry>
        <mesh filename="package://assets/e07_mg996r.stl"/>
      </geometry>
      <material name="e07_mg996r_5_material">
        <color rgba="0.25 0.25 0.25 1"/>
      </material>
    </visual>
    <collision>
      <origin xyz="0.044422 -0.0202089 0.0135385" rpy="1.09062e-14 1.58122e-14 -3.14159"/>
      <geometry>
        <mesh filename="package://assets/e07_mg996r.stl"/>
      </geometry>
    </collision>
    <!-- Part servo_horns_5 -->
    <visual>
      <origin xyz="0.054422 -0.0202089 0.0307885" rpy="-1.5708 -3.06367e-15 3.14159"/>
      <geometry>
        <mesh filename="package://assets/servo_horns.stl"/>
      </geometry>
      <material name="servo_horns_5_material">
        <color rgba="0.25 0.25 0.25 1"/>
      </material>
    </visual>
    <collision>
      <origin xyz="0.054422 -0.0202089 0.0307885" rpy="-1.5708 -3.06367e-15 3.14159"/>
      <geometry>
        <mesh filename="package://assets/servo_horns.stl"/>
      </geometry>
    </collision>
    <!-- Part e07_mg996r_6 -->
    <visual>
      <origin xyz="-0.121348 -0.112882 0.0135385" rpy="-1.84133e-14 -5.47011e-15 0.678221"/>
      <geometry>
        <mesh filename="package://assets/e07_mg996r.stl"/>
      </geometry>
      <material name="e07_mg996r_6_material">
        <color rgba="0.25 0.25 0.25 1"/>
      </material>
    </visual>
    <collision>
      <origin xyz="-0.121348 -0.112882 0.0135385" rpy="-1.84133e-14 -5.47011e-15 0.678221"/>
      <geometry>
        <mesh filename="package://assets/e07_mg996r.stl"/>
      </geometry>
    </collision>
    <!-- Part servo_horns_6 -->
    <visual>
      <origin xyz="-0.129135 -0.119156 0.0307885" rpy="-1.5708 7.46399e-15 0.678221"/>
      <geometry>
        <mesh filename="package://assets/servo_horns.stl"/>
      </geometry>
      <material name="servo_horns_6_material">
        <color rgba="0.25 0.25 0.25 1"/>
      </material>
    </visual>
    <collision>
      <origin xyz="-0.129135 -0.119156 0.0307885" rpy="-1.5708 7.46399e-15 0.678221"/>
      <geometry>
        <mesh filename="package://assets/servo_horns.stl"/>
      </geometry>
    </collision>
  </link>
  <!-- Link righthip -->
  <link name="righthip">
    <inertial>
      <origin xyz="-0.0451285 0.00260019 0.0241834" rpy="0 0 0"/>
      <mass value="0.0839378"/>
      <inertia ixx="3.22234e-05" ixy="1.72216e-06" ixz="-3.44081e-07" iyy="4.58086e-05" iyz="4.48241e-07" izz="2.88934e-05"/>
    </inertial>
    <!-- Part righthip -->
    <visual>
      <origin xyz="-0.180368 -0.005 -0.21218" rpy="-1.5708 4.51609e-17 -5.7343e-14"/>
      <geometry>
        <mesh filename="package://assets/righthip.stl"/>
      </geometry>
      <material name="righthip_material">
        <color rgba="0.25 0.25 0.25 1"/>
      </material>
    </visual>
    <collision>
      <origin xyz="-0.180368 -0.005 -0.21218" rpy="-1.5708 4.51609e-17 -5.7343e-14"/>
      <geometry>
        <mesh filename="package://assets/righthip.stl"/>
      </geometry>
    </collision>
    <!-- Part idler_7 -->
    <visual>
      <origin xyz="-0.06314 -0.199212 0.00418461" rpy="-1.5708 -1.5708 0"/>
      <geometry>
        <mesh filename="package://assets/idler.stl"/>
      </geometry>
      <material name="idler_7_material">
        <color rgba="0.25 0.25 0.25 1"/>
      </material>
    </visual>
    <collision>
      <origin xyz="-0.06314 -0.199212 0.00418461" rpy="-1.5708 -1.5708 0"/>
      <geometry>
        <mesh filename="package://assets/idler.stl"/>
      </geometry>
    </collision>
    <!-- Part e07_mg996r_7 -->
    <visual>
      <origin xyz="-0.053 -0.005 0.0246" rpy="1.5708 -1.5708 0"/>
      <geometry>
        <mesh filename="package://assets/e07_mg996r.stl"/>
      </geometry>
      <material name="e07_mg996r_7_material">
        <color rgba="0.25 0.25 0.25 1"/>
      </material>
    </visual>
    <collision>
      <origin xyz="-0.053 -0.005 0.0246" rpy="1.5708 -1.5708 0"/>
      <geometry>
        <mesh filename="package://assets/e07_mg996r.stl"/>
      </geometry>
    </collision>
    <!-- Part servo_horns_7 -->
    <visual>
      <origin xyz="-0.053 -0.02225 0.0146" rpy="-1.36779e-13 -1.5708 0"/>
      <geometry>
        <mesh filename="package://assets/servo_horns.stl"/>
      </geometry>
      <material name="servo_horns_7_material">
        <color rgba="0.25 0.25 0.25 1"/>
      </material>
    </visual>
    <collision>
      <origin xyz="-0.053 -0.02225 0.0146" rpy="-1.36779e-13 -1.5708 0"/>
      <geometry>
        <mesh filename="package://assets/servo_horns.stl"/>
      </geometry>
    </collision>
  </link>
  <!-- Link tibia -->
  <link name="tibia">
    <inertial>
      <origin xyz="-1.82146e-17 -0.0409873 0.0247148" rpy="0 0 0"/>
      <mass value="0.0352344"/>
      <inertia ixx="5.15258e-05" ixy="1.75673e-21" ixz="5.66802e-21" iyy="2.78079e-05" iyz="-1.87489e-09" izz="2.43045e-05"/>
    </inertial>
    <!-- Part tibia -->
    <visual>
      <origin xyz="-0.005 0.258999 -0.230075" rpy="-1.5708 2.77556e-16 -1.5708"/>
      <geometry>
        <mesh filename="package://assets/tibia.stl"/>
      </geometry>
      <material name="tibia_material">
        <color rgba="0.25 0.25 0.25 1"/>
      </material>
    </visual>
    <collision>
      <origin xyz="-0.005 0.258999 -0.230075" rpy="-1.5708 2.77556e-16 -1.5708"/>
      <geometry>
        <mesh filename="package://assets/tibia.stl"/>
      </geometry>
    </collision>
  </link>
  <!-- Link rightfemur -->
  <link name="rightfemur">
    <inertial>
      <origin xyz="0.00668249 0.0181534 -0.0256184" rpy="0 0 0"/>
      <mass value="0.0986065"/>
      <inertia ixx="0.000112275" ixy="-5.7892e-06" ixz="1.8654e-07" iyy="3.11648e-05" iyz="-3.96641e-06" izz="0.000127723"/>
    </inertial>
    <!-- Part rightfemur -->
    <visual>
      <origin xyz="-0.251053 -0.52013 -0.0284" rpy="5.56777e-14 -5.71765e-15 1.5708"/>
      <geometry>
        <mesh filename="package://assets/rightfemur.stl"/>
      </geometry>
      <material name="rightfemur_material">
        <color rgba="0.25 0.25 0.25 1"/>
      </material>
    </visual>
    <collision>
      <origin xyz="-0.251053 -0.52013 -0.0284" rpy="5.56777e-14 -5.71765e-15 1.5708"/>
      <geometry>
        <mesh filename="package://assets/rightfemur.stl"/>
      </geometry>
    </collision>
    <!-- Part idler_8 -->
    <visual>
      <origin xyz="-0.0104154 0.01014 0.175812" rpy="-3.14159 -4.92939e-14 5.62328e-14"/>
      <geometry>
        <mesh filename="package://assets/idler.stl"/>
      </geometry>
      <material name="idler_8_material">
        <color rgba="0.25 0.25 0.25 1"/>
      </material>
    </visual>
    <collision>
      <origin xyz="-0.0104154 0.01014 0.175812" rpy="-3.14159 -4.92939e-14 5.62328e-14"/>
      <geometry>
        <mesh filename="package://assets/idler.stl"/>
      </geometry>
    </collision>
    <!-- Part e07_mg996r_8 -->
    <visual>
      <origin xyz="0.01 3.56659e-15 -0.0184" rpy="5.71765e-15 5.57332e-14 3.05589e-14"/>
      <geometry>
        <mesh filename="package://assets/e07_mg996r.stl"/>
      </geometry>
      <material name="e07_mg996r_8_material">
        <color rgba="0.25 0.25 0.25 1"/>
      </material>
    </visual>
    <collision>
      <origin xyz="0.01 3.56659e-15 -0.0184" rpy="5.71765e-15 5.57332e-14 3.05589e-14"/>
      <geometry>
        <mesh filename="package://assets/e07_mg996r.stl"/>
      </geometry>
    </collision>
    <!-- Part servo_horns_8 -->
    <visual>
      <origin xyz="-2.77556e-17 0 -0.00115" rpy="-1.5708 5.55112e-17 2.77556e-17"/>
      <geometry>
        <mesh filename="package://assets/servo_horns.stl"/>
      </geometry>
      <material name="servo_horns_8_material">
        <color rgba="0.25 0.25 0.25 1"/>
      </material>
    </visual>
    <collision>
      <origin xyz="-2.77556e-17 0 -0.00115" rpy="-1.5708 5.55112e-17 2.77556e-17"/>
      <geometry>
        <mesh filename="package://assets/servo_horns.stl"/>
      </geometry>
    </collision>
  </link>
  <!-- Joint from tibia to rightfemur -->
  <joint name="femur_r1" type="revolute">
    <origin xyz="-3.1225e-17 -0.085 0" rpy="3.14159 -5.55112e-17 0.959931"/>
    <parent link="tibia"/>
    <child link="rightfemur"/>
    <axis xyz="0 0 1"/>
    <limit effort="10" velocity="6" lower="-1.22173" upper="0.959931"/>
    <joint_properties friction="0.5"/>
  </joint>
  <!-- Joint from righthip to tibia -->
  <joint name="tibia_r1" type="revolute">
    <origin xyz="-0.06 -0.0234 0.0146" rpy="-1.5708 -1.5708 0"/>
    <parent link="righthip"/>
    <child link="tibia"/>
    <axis xyz="0 0 1"/>
    <limit effort="10" velocity="6" lower="-1.22173" upper="1.06581e-14"/>
    <joint_properties friction="0.5"/>
  </joint>
  <!-- Joint from lowerbody to righthip -->
  <joint name="hip_r1" type="revolute">
    <origin xyz="0.052388 -0.119156 0.0319385" rpy="3.14159 9.93205e-15 2.46337"/>
    <parent link="lowerbody"/>
    <child link="righthip"/>
    <axis xyz="0 0 1"/>
    <limit effort="10" velocity="6" lower="-0.523599" upper="0.523599"/>
    <joint_properties friction="0.5"/>
  </joint>
  <!-- Link righthip_2 -->
  <link name="righthip_2">
    <inertial>
      <origin xyz="-0.0451512 0.00217011 0.0241834" rpy="0 0 0"/>
      <mass value="0.0839378"/>
      <inertia ixx="3.21918e-05" ixy="1.59242e-06" ixz="-3.48336e-07" iyy="4.58402e-05" iyz="4.44942e-07" izz="2.88934e-05"/>
    </inertial>
    <!-- Part righthip_2 -->
    <visual>
      <origin xyz="-0.180312 -0.00671823 -0.21218" rpy="-1.5708 -1.87498e-16 0.00952765"/>
      <geometry>
        <mesh filename="package://assets/righthip.stl"/>
      </geometry>
      <material name="righthip_2_material">
        <color rgba="0.25 0.25 0.25 1"/>
      </material>
    </visual>
    <collision>
      <origin xyz="-0.180312 -0.00671823 -0.21218" rpy="-1.5708 -1.87498e-16 0.00952765"/>
      <geometry>
        <mesh filename="package://assets/righthip.stl"/>
      </geometry>
    </collision>
    <!-- Part idler_9 -->
    <visual>
      <origin xyz="-0.0612392 -0.199804 0.00418461" rpy="-1.56127 -1.5708 0"/>
      <geometry>
        <mesh filename="package://assets/idler.stl"/>
      </geometry>
      <material name="idler_9_material">
        <color rgba="0.25 0.25 0.25 1"/>
      </material>
    </visual>
    <collision>
      <origin xyz="-0.0612392 -0.199804 0.00418461" rpy="-1.56127 -1.5708 0"/>
      <geometry>
        <mesh filename="package://assets/idler.stl"/>
      </geometry>
    </collision>
    <!-- Part e07_mg996r_9 -->
    <visual>
      <origin xyz="-0.05295 -0.00550473 0.0246" rpy="1.58032 -1.5708 0"/>
      <geometry>
        <mesh filename="package://assets/e07_mg996r.stl"/>
      </geometry>
      <material name="e07_mg996r_9_material">
        <color rgba="0.25 0.25 0.25 1"/>
      </material>
    </visual>
    <collision>
      <origin xyz="-0.05295 -0.00550473 0.0246" rpy="1.58032 -1.5708 0"/>
      <geometry>
        <mesh filename="package://assets/e07_mg996r.stl"/>
      </geometry>
    </collision>
    <!-- Part servo_horns_9 -->
    <visual>
      <origin xyz="-0.0527856 -0.0227539 0.0146" rpy="0.00952765 -1.5708 0"/>
      <geometry>
        <mesh filename="package://assets/servo_horns.stl"/>
      </geometry>
      <material name="servo_horns_9_material">
        <color rgba="0.25 0.25 0.25 1"/>
      </material>
    </visual>
    <collision>
      <origin xyz="-0.0527856 -0.0227539 0.0146" rpy="0.00952765 -1.5708 0"/>
      <geometry>
        <mesh filename="package://assets/servo_horns.stl"/>
      </geometry>
    </collision>
  </link>
  <!-- Link tibia_2 -->
  <link name="tibia_2">
    <inertial>
      <origin xyz="7.89299e-17 -0.0409873 0.0247148" rpy="0 0 0"/>
      <mass value="0.0352344"/>
      <inertia ixx="5.15258e-05" ixy="4.70882e-20" ixz="-3.18264e-21" iyy="2.78079e-05" iyz="-1.87489e-09" izz="2.43045e-05"/>
    </inertial>
    <!-- Part tibia_2 -->
    <visual>
      <origin xyz="-0.005 0.258999 -0.230075" rpy="-1.5708 1.17961e-16 -1.5708"/>
      <geometry>
        <mesh filename="package://assets/tibia.stl"/>
      </geometry>
      <material name="tibia_2_material">
        <color rgba="0.25 0.25 0.25 1"/>
      </material>
    </visual>
    <collision>
      <origin xyz="-0.005 0.258999 -0.230075" rpy="-1.5708 1.17961e-16 -1.5708"/>
      <geometry>
        <mesh filename="package://assets/tibia.stl"/>
      </geometry>
    </collision>
  </link>
  <!-- Link rightfemur_2 -->
  <link name="rightfemur_2">
    <inertial>
      <origin xyz="0.00668249 0.0181534 -0.0256184" rpy="0 0 0"/>
      <mass value="0.0986065"/>
      <inertia ixx="0.000112275" ixy="-5.7892e-06" ixz="1.8654e-07" iyy="3.11648e-05" iyz="-3.96641e-06" izz="0.000127723"/>
    </inertial>
    <!-- Part rightfemur_2 -->
    <visual>
      <origin xyz="-0.251053 -0.52013 -0.0284" rpy="2.76706e-14 -7.40033e-15 1.5708"/>
      <geometry>
        <mesh filename="package://assets/rightfemur.stl"/>
      </geometry>
      <material name="rightfemur_2_material">
        <color rgba="0.25 0.25 0.25 1"/>
      </material>
    </visual>
    <collision>
      <origin xyz="-0.251053 -0.52013 -0.0284" rpy="2.76706e-14 -7.40033e-15 1.5708"/>
      <geometry>
        <mesh filename="package://assets/rightfemur.stl"/>
      </geometry>
    </collision>
    <!-- Part idler_10 -->
    <visual>
      <origin xyz="-0.0104154 0.01014 0.175812" rpy="-3.14159 -7.61179e-14 3.94123e-14"/>
      <geometry>
        <mesh filename="package://assets/idler.stl"/>
      </geometry>
      <material name="idler_10_material">
        <color rgba="0.25 0.25 0.25 1"/>
      </material>
    </visual>
    <collision>
      <origin xyz="-0.0104154 0.01014 0.175812" rpy="-3.14159 -7.61179e-14 3.94123e-14"/>
      <geometry>
        <mesh filename="package://assets/idler.stl"/>
      </geometry>
    </collision>
    <!-- Part e07_mg996r_10 -->
    <visual>
      <origin xyz="0.01 2.05391e-15 -0.0184" rpy="7.4012e-15 2.76688e-14 1.41064e-14"/>
      <geometry>
        <mesh filename="package://assets/e07_mg996r.stl"/>
      </geometry>
      <material name="e07_mg996r_10_material">
        <color rgba="0.25 0.25 0.25 1"/>
      </material>
    </visual>
    <collision>
      <origin xyz="0.01 2.05391e-15 -0.0184" rpy="7.4012e-15 2.76688e-14 1.41064e-14"/>
      <geometry>
        <mesh filename="package://assets/e07_mg996r.stl"/>
      </geometry>
    </collision>
    <!-- Part servo_horns_10 -->
    <visual>
      <origin xyz="-2.77556e-17 -2.77556e-17 -0.00115" rpy="-1.5708 8.67362e-19 -3.04593e-17"/>
      <geometry>
        <mesh filename="package://assets/servo_horns.stl"/>
      </geometry>
      <material name="servo_horns_10_material">
        <color rgba="0.25 0.25 0.25 1"/>
      </material>
    </visual>
    <collision>
      <origin xyz="-2.77556e-17 -2.77556e-17 -0.00115" rpy="-1.5708 8.67362e-19 -3.04593e-17"/>
      <geometry>
        <mesh filename="package://assets/servo_horns.stl"/>
      </geometry>
    </collision>
  </link>
  <!-- Joint from tibia_2 to rightfemur_2 -->
  <joint name="femur_r2" type="revolute">
    <origin xyz="1.63064e-16 -0.085 -1.75641e-17" rpy="-3.14159 3.72966e-17 0.959931"/>
    <parent link="tibia_2"/>
    <child link="rightfemur_2"/>
    <axis xyz="0 0 1"/>
    <limit effort="10" velocity="6" lower="-1.22173" upper="0.959931"/>
    <joint_properties friction="0.5"/>
  </joint>
  <!-- Joint from righthip_2 to tibia_2 -->
  <joint name="tibia_r2" type="revolute">
    <origin xyz="-0.0597743 -0.0239706 0.0146" rpy="-1.56127 -1.5708 0"/>
    <parent link="righthip_2"/>
    <child link="tibia_2"/>
    <axis xyz="0 0 1"/>
    <limit effort="10" velocity="6" lower="-1.22173" upper="3.81917e-14"/>
    <joint_properties friction="0.5"/>
  </joint>
  <!-- Joint from lowerbody to righthip_2 -->
  <joint name="hip_r2" type="revolute">
    <origin xyz="0.054422 -0.0202089 0.0319385" rpy="3.14159 -3.06367e-15 3.14159"/>
    <parent link="lowerbody"/>
    <child link="righthip_2"/>
    <axis xyz="0 0 1"/>
    <limit effort="10" velocity="6" lower="-0.533126" upper="0.514071"/>
    <joint_properties friction="0.5"/>
  </joint>
  <!-- Link righthip_3 -->
  <link name="righthip_3">
    <inertial>
      <origin xyz="-0.0451512 0.00217011 0.0241834" rpy="0 0 0"/>
      <mass value="0.0839378"/>
      <inertia ixx="3.21918e-05" ixy="1.59242e-06" ixz="-3.48336e-07" iyy="4.58402e-05" iyz="4.44942e-07" izz="2.88934e-05"/>
    </inertial>
    <!-- Part righthip_3 -->
    <visual>
      <origin xyz="-0.180312 -0.00671823 -0.21218" rpy="-1.5708 -2.29782e-16 0.00952765"/>
      <geometry>
        <mesh filename="package://assets/righthip.stl"/>
      </geometry>
      <material name="righthip_3_material">
        <color rgba="0.25 0.25 0.25 1"/>
      </material>
    </visual>
    <collision>
      <origin xyz="-0.180312 -0.00671823 -0.21218" rpy="-1.5708 -2.29782e-16 0.00952765"/>
      <geometry>
        <mesh filename="package://assets/righthip.stl"/>
      </geometry>
    </collision>
    <!-- Part idler_11 -->
    <visual>
      <origin xyz="-0.0612392 -0.199804 0.00418461" rpy="-1.56127 -1.5708 0"/>
      <geometry>
        <mesh filename="package://assets/idler.stl"/>
      </geometry>
      <material name="idler_11_material">
        <color rgba="0.25 0.25 0.25 1"/>
      </material>
    </visual>
    <collision>
      <origin xyz="-0.0612392 -0.199804 0.00418461" rpy="-1.56127 -1.5708 0"/>
      <geometry>
        <mesh filename="package://assets/idler.stl"/>
      </geometry>
    </collision>
    <!-- Part e07_mg996r_11 -->
    <visual>
      <origin xyz="-0.05295 -0.00550473 0.0246" rpy="1.58032 -1.5708 0"/>
      <geometry>
        <mesh filename="package://assets/e07_mg996r.stl"/>
      </geometry>
      <material name="e07_mg996r_11_material">
        <color rgba="0.25 0.25 0.25 1"/>
      </material>
    </visual>
    <collision>
      <origin xyz="-0.05295 -0.00550473 0.0246" rpy="1.58032 -1.5708 0"/>
      <geometry>
        <mesh filename="package://assets/e07_mg996r.stl"/>
      </geometry>
    </collision>
    <!-- Part servo_horns_11 -->
    <visual>
      <origin xyz="-0.0527856 -0.0227539 0.0146" rpy="0.00952765 -1.5708 0"/>
      <geometry>
        <mesh filename="package://assets/servo_horns.stl"/>
      </geometry>
      <material name="servo_horns_11_material">
        <color rgba="0.25 0.25 0.25 1"/>
      </material>
    </visual>
    <collision>
      <origin xyz="-0.0527856 -0.0227539 0.0146" rpy="0.00952765 -1.5708 0"/>
      <geometry>
        <mesh filename="package://assets/servo_horns.stl"/>
      </geometry>
    </collision>
  </link>
  <!-- Link tibia_3 -->
  <link name="tibia_3">
    <inertial>
      <origin xyz="-4.85723e-17 -0.0409873 0.0247148" rpy="0 0 0"/>
      <mass value="0.0352344"/>
      <inertia ixx="5.15258e-05" ixy="-5.11868e-20" ixz="-5.03478e-20" iyy="2.78079e-05" iyz="-1.87489e-09" izz="2.43045e-05"/>
    </inertial>
    <!-- Part tibia_3 -->
    <visual>
      <origin xyz="-0.005 0.258999 -0.230075" rpy="-1.5708 -1.66533e-16 -1.5708"/>
      <geometry>
        <mesh filename="package://assets/tibia.stl"/>
      </geometry>
      <material name="tibia_3_material">
        <color rgba="0.25 0.25 0.25 1"/>
      </material>
    </visual>
    <collision>
      <origin xyz="-0.005 0.258999 -0.230075" rpy="-1.5708 -1.66533e-16 -1.5708"/>
      <geometry>
        <mesh filename="package://assets/tibia.stl"/>
      </geometry>
    </collision>
  </link>
  <!-- Link rightfemur_3 -->
  <link name="rightfemur_3">
    <inertial>
      <origin xyz="0.00668249 0.0181534 -0.0256184" rpy="0 0 0"/>
      <mass value="0.0986065"/>
      <inertia ixx="0.000112275" ixy="-5.7892e-06" ixz="1.8654e-07" iyy="3.11648e-05" iyz="-3.96641e-06" izz="0.000127723"/>
    </inertial>
    <!-- Part rightfemur_3 -->
    <visual>
      <origin xyz="-0.251053 -0.52013 -0.0284" rpy="1.46161e-13 1.3417e-13 1.5708"/>
      <geometry>
        <mesh filename="package://assets/rightfemur.stl"/>
      </geometry>
      <material name="rightfemur_3_material">
        <color rgba="0.25 0.25 0.25 1"/>
      </material>
    </visual>
    <collision>
      <origin xyz="-0.251053 -0.52013 -0.0284" rpy="1.46161e-13 1.3417e-13 1.5708"/>
      <geometry>
        <mesh filename="package://assets/rightfemur.stl"/>
      </geometry>
    </collision>
    <!-- Part idler_12 -->
    <visual>
      <origin xyz="-0.0104154 0.01014 0.175812" rpy="3.14159 2.43139e-14 -1.43843e-13"/>
      <geometry>
        <mesh filename="package://assets/idler.stl"/>
      </geometry>
      <material name="idler_12_material">
        <color rgba="0.25 0.25 0.25 1"/>
      </material>
    </visual>
    <collision>
      <origin xyz="-0.0104154 0.01014 0.175812" rpy="3.14159 2.43139e-14 -1.43843e-13"/>
      <geometry>
        <mesh filename="package://assets/idler.stl"/>
      </geometry>
    </collision>
    <!-- Part e07_mg996r_12 -->
    <visual>
      <origin xyz="0.01 2.73392e-15 -0.0184" rpy="-1.3417e-13 1.46272e-13 -5.78843e-14"/>
      <geometry>
        <mesh filename="package://assets/e07_mg996r.stl"/>
      </geometry>
      <material name="e07_mg996r_12_material">
        <color rgba="0.25 0.25 0.25 1"/>
      </material>
    </visual>
    <collision>
      <origin xyz="0.01 2.73392e-15 -0.0184" rpy="-1.3417e-13 1.46272e-13 -5.78843e-14"/>
      <geometry>
        <mesh filename="package://assets/e07_mg996r.stl"/>
      </geometry>
    </collision>
    <!-- Part servo_horns_12 -->
    <visual>
      <origin xyz="0 1.38778e-17 -0.00115" rpy="-1.5708 -0 -5.55112e-17"/>
      <geometry>
        <mesh filename="package://assets/servo_horns.stl"/>
      </geometry>
      <material name="servo_horns_12_material">
        <color rgba="0.25 0.25 0.25 1"/>
      </material>
    </visual>
    <collision>
      <origin xyz="0 1.38778e-17 -0.00115" rpy="-1.5708 -0 -5.55112e-17"/>
      <geometry>
        <mesh filename="package://assets/servo_horns.stl"/>
      </geometry>
    </collision>
  </link>
  <!-- Joint from tibia_3 to rightfemur_3 -->
  <joint name="femur_r3" type="revolute">
    <origin xyz="-1.9082e-16 -0.085 -2.77556e-17" rpy="-3.14159 2.22045e-16 0.959931"/>
    <parent link="tibia_3"/>
    <child link="rightfemur_3"/>
    <axis xyz="0 0 1"/>
    <limit effort="10" velocity="6" lower="-1.22173" upper="0.959931"/>
    <joint_properties friction="0.5"/>
  </joint>
  <!-- Joint from righthip_3 to tibia_3 -->
  <joint name="tibia_r3" type="revolute">
    <origin xyz="-0.0597743 -0.0239706 0.0146" rpy="-1.56127 -1.5708 0"/>
    <parent link="righthip_3"/>
    <child link="tibia_3"/>
    <axis xyz="0 0 1"/>
    <limit effort="10" velocity="6" lower="-1.22173" upper="7.99361e-15"/>
    <joint_properties friction="0.5"/>
  </joint>
  <!-- Joint from lowerbody to righthip_3 -->
  <joint name="hip_r3" type="revolute">
    <origin xyz="0.0485111 0.0663725 0.0319385" rpy="-3.14159 -2.57421e-15 -2.70526"/>
    <parent link="lowerbody"/>
    <child link="righthip_3"/>
    <axis xyz="0 0 1"/>
    <limit effort="10" velocity="6" lower="-0.533126" upper="0.514071"/>
    <joint_properties friction="0.5"/>
  </joint>
  <!-- Link righthip_4 -->
  <link name="righthip_4">
    <inertial>
      <origin xyz="-0.0450964 -0.0030359 0.0243878" rpy="0 0 0"/>
      <mass value="0.0839378"/>
      <inertia ixx="3.22477e-05" ixy="-1.84795e-06" ixz="-2.00048e-07" iyy="4.57606e-05" iyz="-4.29052e-07" izz="2.88839e-05"/>
    </inertial>
    <!-- Part righthip_4 -->
    <visual>
      <origin xyz="-0.180312 -0.00671823 -0.21218" rpy="-1.5708 -5.30027e-16 0.00952765"/>
      <geometry>
        <mesh filename="package://assets/righthip.stl"/>
      </geometry>
      <material name="righthip_4_material">
        <color rgba="0.25 0.25 0.25 1"/>
      </material>
    </visual>
    <collision>
      <origin xyz="-0.180312 -0.00671823 -0.21218" rpy="-1.5708 -5.30027e-16 0.00952765"/>
      <geometry>
        <mesh filename="package://assets/righthip.stl"/>
      </geometry>
    </collision>
    <!-- Part idler_13 -->
    <visual>
      <origin xyz="-0.044756 0.198794 0.00448461" rpy="1.58032 -1.5708 0"/>
      <geometry>
        <mesh filename="package://assets/idler.stl"/>
      </geometry>
      <material name="idler_13_material">
        <color rgba="0.25 0.25 0.25 1"/>
      </material>
    </visual>
    <collision>
      <origin xyz="-0.044756 0.198794 0.00448461" rpy="1.58032 -1.5708 0"/>
      <geometry>
        <mesh filename="package://assets/idler.stl"/>
      </geometry>
    </collision>
    <!-- Part e07_mg996r_13 -->
    <visual>
      <origin xyz="-0.0530452 0.00449482 0.0249" rpy="-1.56127 -1.5708 0"/>
      <geometry>
        <mesh filename="package://assets/e07_mg996r.stl"/>
      </geometry>
      <material name="e07_mg996r_13_material">
        <color rgba="0.25 0.25 0.25 1"/>
      </material>
    </visual>
    <collision>
      <origin xyz="-0.0530452 0.00449482 0.0249" rpy="-1.56127 -1.5708 0"/>
      <geometry>
        <mesh filename="package://assets/e07_mg996r.stl"/>
      </geometry>
    </collision>
    <!-- Part servo_horns_13 -->
    <visual>
      <origin xyz="-0.0532096 0.021744 0.0149" rpy="-3.13207 -1.5708 0"/>
      <geometry>
        <mesh filename="package://assets/servo_horns.stl"/>
      </geometry>
      <material name="servo_horns_13_material">
        <color rgba="0.25 0.25 0.25 1"/>
      </material>
    </visual>
    <collision>
      <origin xyz="-0.0532096 0.021744 0.0149" rpy="-3.13207 -1.5708 0"/>
      <geometry>
        <mesh filename="package://assets/servo_horns.stl"/>
      </geometry>
    </collision>
  </link>
  <!-- Link tibia_4 -->
  <link name="tibia_4">
    <inertial>
      <origin xyz="0.0409873 -8.67362e-19 0.0247148" rpy="0 0 0"/>
      <mass value="0.0352344"/>
      <inertia ixx="2.78079e-05" ixy="0" ixz="1.87489e-09" iyy="5.15258e-05" iyz="4.06467e-35" izz="2.43045e-05"/>
    </inertial>
    <!-- Part tibia_4 -->
    <visual>
      <origin xyz="-0.258999 -0.005 -0.230075" rpy="-1.5708 -5.55112e-17 0"/>
      <geometry>
        <mesh filename="package://assets/tibia.stl"/>
      </geometry>
      <material name="tibia_4_material">
        <color rgba="0.25 0.25 0.25 1"/>
      </material>
    </visual>
    <collision>
      <origin xyz="-0.258999 -0.005 -0.230075" rpy="-1.5708 -5.55112e-17 0"/>
      <geometry>
        <mesh filename="package://assets/tibia.stl"/>
      </geometry>
    </collision>
  </link>
  <!-- Link rightfemur_4 -->
  <link name="rightfemur_4">
    <inertial>
      <origin xyz="0.00668249 -0.0181489 -0.0256134" rpy="0 0 0"/>
      <mass value="0.0986065"/>
      <inertia ixx="0.000112293" ixy="5.79279e-06" ixz="1.84967e-07" iyy="3.1167e-05" iyz="3.96574e-06" izz="0.000127739"/>
    </inertial>
    <!-- Part rightfemur_4 -->
    <visual>
      <origin xyz="-0.251053 0.52013 -0.0184" rpy="3.14159 4.56857e-14 -1.5708"/>
      <geometry>
        <mesh filename="package://assets/rightfemur.stl"/>
      </geometry>
      <material name="rightfemur_4_material">
        <color rgba="0.25 0.25 0.25 1"/>
      </material>
    </visual>
    <collision>
      <origin xyz="-0.251053 0.52013 -0.0184" rpy="3.14159 4.56857e-14 -1.5708"/>
      <geometry>
        <mesh filename="package://assets/rightfemur.stl"/>
      </geometry>
    </collision>
    <!-- Part idler_14 -->
    <visual>
      <origin xyz="-0.0104154 0.01014 0.175812" rpy="-3.14159 -1.41664e-13 -8.34055e-14"/>
      <geometry>
        <mesh filename="package://assets/idler.stl"/>
      </geometry>
      <material name="idler_14_material">
        <color rgba="0.25 0.25 0.25 1"/>
      </material>
    </visual>
    <collision>
      <origin xyz="-0.0104154 0.01014 0.175812" rpy="-3.14159 -1.41664e-13 -8.34055e-14"/>
      <geometry>
        <mesh filename="package://assets/idler.stl"/>
      </geometry>
    </collision>
    <!-- Part e07_mg996r_14 -->
    <visual>
      <origin xyz="0.01 -7.35523e-16 -0.0184" rpy="4.56302e-14 1.12077e-13 4.588e-14"/>
      <geometry>
        <mesh filename="package://assets/e07_mg996r.stl"/>
      </geometry>
      <material name="e07_mg996r_14_material">
        <color rgba="0.25 0.25 0.25 1"/>
      </material>
    </visual>
    <collision>
      <origin xyz="0.01 -7.35523e-16 -0.0184" rpy="4.56302e-14 1.12077e-13 4.588e-14"/>
      <geometry>
        <mesh filename="package://assets/e07_mg996r.stl"/>
      </geometry>
    </collision>
    <!-- Part servo_horns_14 -->
    <visual>
      <origin xyz="8.32667e-17 1.38778e-17 -0.00115" rpy="-1.5708 -0 -8.32667e-17"/>
      <geometry>
        <mesh filename="package://assets/servo_horns.stl"/>
      </geometry>
      <material name="servo_horns_14_material">
        <color rgba="0.25 0.25 0.25 1"/>
      </material>
    </visual>
    <collision>
      <origin xyz="8.32667e-17 1.38778e-17 -0.00115" rpy="-1.5708 -0 -8.32667e-17"/>
      <geometry>
        <mesh filename="package://assets/servo_horns.stl"/>
      </geometry>
    </collision>
  </link>
  <!-- Joint from tibia_4 to rightfemur_4 -->
  <joint name="femur_l1" type="revolute">
    <origin xyz="0.085 -3.46945e-18 -2.77556e-17" rpy="-3.14159 1.11022e-16 -2.53073"/>
    <parent link="tibia_4"/>
    <child link="rightfemur_4"/>
    <axis xyz="0 0 1"/>
    <limit effort="10" velocity="6" lower="-0.959931" upper="1.22173"/>
    <joint_properties friction="0.5"/>
  </joint>
  <!-- Joint from righthip_4 to tibia_4 -->
  <joint name="tibia_l1" type="revolute">
    <origin xyz="-0.0532205 0.022894 0.0149" rpy="-1.5708 -7.54732e-15 -3.13207"/>
    <parent link="righthip_4"/>
    <child link="tibia_4"/>
    <axis xyz="0 0 1"/>
    <limit effort="10" velocity="6" lower="0" upper="1.22173"/>
    <joint_properties friction="0.5"/>
  </joint>
  <!-- Joint from lowerbody to righthip_4 -->
  <joint name="hip_l1" type="revolute">
    <origin xyz="-0.129135 -0.119156 0.0319385" rpy="3.14159 7.46399e-15 0.678221"/>
    <parent link="lowerbody"/>
    <child link="righthip_4"/>
    <axis xyz="0 0 1"/>
    <limit effort="10" velocity="6" lower="-0.533126" upper="0.514071"/>
    <joint_properties friction="0.5"/>
  </joint>
  <!-- Link righthip_5 -->
  <link name="righthip_5">
    <inertial>
      <origin xyz="-0.0451233 -0.00260611 0.0243878" rpy="0 0 0"/>
      <mass value="0.0839378"/>
      <inertia ixx="3.22137e-05" ixy="-1.71888e-06" ixz="-2.04127e-07" iyy="4.57946e-05" iyz="-4.27126e-07" izz="2.88839e-05"/>
    </inertial>
    <!-- Part righthip_5 -->
    <visual>
      <origin xyz="-0.180368 -0.005 -0.21218" rpy="-1.5708 -6.12323e-17 1.14806e-13"/>
      <geometry>
        <mesh filename="package://assets/righthip.stl"/>
      </geometry>
      <material name="righthip_5_material">
        <color rgba="0.25 0.25 0.25 1"/>
      </material>
    </visual>
    <collision>
      <origin xyz="-0.180368 -0.005 -0.21218" rpy="-1.5708 -6.12323e-17 1.14806e-13"/>
      <geometry>
        <mesh filename="package://assets/righthip.stl"/>
      </geometry>
    </collision>
    <!-- Part idler_15 -->
    <visual>
      <origin xyz="-0.04286 0.199212 0.00448461" rpy="1.5708 -1.5708 0"/>
      <geometry>
        <mesh filename="package://assets/idler.stl"/>
      </geometry>
      <material name="idler_15_material">
        <color rgba="0.25 0.25 0.25 1"/>
      </material>
    </visual>
    <collision>
      <origin xyz="-0.04286 0.199212 0.00448461" rpy="1.5708 -1.5708 0"/>
      <geometry>
        <mesh filename="package://assets/idler.stl"/>
      </geometry>
    </collision>
    <!-- Part e07_mg996r_15 -->
    <visual>
      <origin xyz="-0.053 0.005 0.0249" rpy="-1.5708 -1.5708 0"/>
      <geometry>
        <mesh filename="package://assets/e07_mg996r.stl"/>
      </geometry>
      <material name="e07_mg996r_15_material">
        <color rgba="0.25 0.25 0.25 1"/>
      </material>
    </visual>
    <collision>
      <origin xyz="-0.053 0.005 0.0249" rpy="-1.5708 -1.5708 0"/>
      <geometry>
        <mesh filename="package://assets/e07_mg996r.stl"/>
      </geometry>
    </collision>
    <!-- Part servo_horns_15 -->
    <visual>
      <origin xyz="-0.053 0.02225 0.0149" rpy="3.14159 -1.5708 0"/>
      <geometry>
        <mesh filename="package://assets/servo_horns.stl"/>
      </geometry>
      <material name="servo_horns_15_material">
        <color rgba="0.25 0.25 0.25 1"/>
      </material>
    </visual>
    <collision>
      <origin xyz="-0.053 0.02225 0.0149" rpy="3.14159 -1.5708 0"/>
      <geometry>
        <mesh filename="package://assets/servo_horns.stl"/>
      </geometry>
    </collision>
  </link>
  <!-- Link tibia_5 -->
  <link name="tibia_5">
    <inertial>
      <origin xyz="0.0409873 -8.67362e-19 0.0247148" rpy="0 0 0"/>
      <mass value="0.0352344"/>
      <inertia ixx="2.78079e-05" ixy="8.34836e-35" ixz="1.87489e-09" iyy="5.15258e-05" iyz="8.3225e-40" izz="2.43045e-05"/>
    </inertial>
    <!-- Part tibia_5 -->
    <visual>
      <origin xyz="-0.258999 -0.005 -0.230075" rpy="-1.5708 -0 4.43893e-31"/>
      <geometry>
        <mesh filename="package://assets/tibia.stl"/>
      </geometry>
      <material name="tibia_5_material">
        <color rgba="0.25 0.25 0.25 1"/>
      </material>
    </visual>
    <collision>
      <origin xyz="-0.258999 -0.005 -0.230075" rpy="-1.5708 -0 4.43893e-31"/>
      <geometry>
        <mesh filename="package://assets/tibia.stl"/>
      </geometry>
    </collision>
  </link>
  <!-- Link rightfemur_5 -->
  <link name="rightfemur_5">
    <inertial>
      <origin xyz="0.00668249 -0.0181489 -0.0256134" rpy="0 0 0"/>
      <mass value="0.0986065"/>
      <inertia ixx="0.000112293" ixy="5.79279e-06" ixz="1.84967e-07" iyy="3.1167e-05" iyz="3.96574e-06" izz="0.000127739"/>
    </inertial>
    <!-- Part rightfemur_5 -->
    <visual>
      <origin xyz="-0.251053 0.52013 -0.0184" rpy="-3.14159 1.82778e-13 -1.5708"/>
      <geometry>
        <mesh filename="package://assets/rightfemur.stl"/>
      </geometry>
      <material name="rightfemur_5_material">
        <color rgba="0.25 0.25 0.25 1"/>
      </material>
    </visual>
    <collision>
      <origin xyz="-0.251053 0.52013 -0.0184" rpy="-3.14159 1.82778e-13 -1.5708"/>
      <geometry>
        <mesh filename="package://assets/rightfemur.stl"/>
      </geometry>
    </collision>
    <!-- Part idler_16 -->
    <visual>
      <origin xyz="-0.0104154 0.01014 0.175812" rpy="-3.14159 -1.61676e-13 3.06635e-13"/>
      <geometry>
        <mesh filename="package://assets/idler.stl"/>
      </geometry>
      <material name="idler_16_material">
        <color rgba="0.25 0.25 0.25 1"/>
      </material>
    </visual>
    <collision>
      <origin xyz="-0.0104154 0.01014 0.175812" rpy="-3.14159 -1.61676e-13 3.06635e-13"/>
      <geometry>
        <mesh filename="package://assets/idler.stl"/>
      </geometry>
    </collision>
    <!-- Part e07_mg996r_16 -->
    <visual>
      <origin xyz="0.01 2.69229e-15 -0.0184" rpy="1.82778e-13 -1.11994e-13 2.91252e-13"/>
      <geometry>
        <mesh filename="package://assets/e07_mg996r.stl"/>
      </geometry>
      <material name="e07_mg996r_16_material">
        <color rgba="0.25 0.25 0.25 1"/>
      </material>
    </visual>
    <collision>
      <origin xyz="0.01 2.69229e-15 -0.0184" rpy="1.82778e-13 -1.11994e-13 2.91252e-13"/>
      <geometry>
        <mesh filename="package://assets/e07_mg996r.stl"/>
      </geometry>
    </collision>
    <!-- Part servo_horns_16 -->
    <visual>
      <origin xyz="-5.55112e-17 0 -0.00115" rpy="-1.5708 -0 4.0323e-19"/>
      <geometry>
        <mesh filename="package://assets/servo_horns.stl"/>
      </geometry>
      <material name="servo_horns_16_material">
        <color rgba="0.25 0.25 0.25 1"/>
      </material>
    </visual>
    <collision>
      <origin xyz="-5.55112e-17 0 -0.00115" rpy="-1.5708 -0 4.0323e-19"/>
      <geometry>
        <mesh filename="package://assets/servo_horns.stl"/>
      </geometry>
    </collision>
  </link>
  <!-- Joint from tibia_5 to rightfemur_5 -->
  <joint name="femur_l2" type="revolute">
    <origin xyz="0.085 3.46945e-18 -7.99785e-18" rpy="-3.14159 6.12323e-17 -2.53073"/>
    <parent link="tibia_5"/>
    <child link="rightfemur_5"/>
    <axis xyz="0 0 1"/>
    <limit effort="10" velocity="6" lower="-0.959931" upper="1.22173"/>
    <joint_properties friction="0.5"/>
  </joint>
  <!-- Joint from righthip_5 to tibia_5 -->
  <joint name="tibia_l2" type="revolute">
    <origin xyz="-0.053 0.0234 0.0149" rpy="-1.5708 8.66856e-15 3.14159"/>
    <parent link="righthip_5"/>
    <child link="tibia_5"/>
    <axis xyz="0 0 1"/>
    <limit effort="10" velocity="6" lower="0" upper="1.22173"/>
    <joint_properties friction="0.5"/>
  </joint>
  <!-- Joint from lowerbody to righthip_5 -->
  <joint name="hip_l2" type="revolute">
    <origin xyz="-0.131169 -0.0202089 0.0319385" rpy="-3.14159 -1.75355e-16 -4.49293e-15"/>
    <parent link="lowerbody"/>
    <child link="righthip_5"/>
    <axis xyz="0 0 1"/>
    <limit effort="10" velocity="6" lower="-0.523599" upper="0.523599"/>
    <joint_properties friction="0.5"/>
  </joint>
  <!-- Link righthip_6 -->
  <link name="righthip_6">
    <inertial>
      <origin xyz="-0.0451233 -0.00260611 0.0243878" rpy="0 0 0"/>
      <mass value="0.0839378"/>
      <inertia ixx="3.22137e-05" ixy="-1.71888e-06" ixz="-2.04127e-07" iyy="4.57946e-05" iyz="-4.27126e-07" izz="2.88839e-05"/>
    </inertial>
    <!-- Part righthip_6 -->
    <visual>
      <origin xyz="-0.180368 -0.005 -0.21218" rpy="-1.5708 9.66473e-16 -3.31402e-14"/>
      <geometry>
        <mesh filename="package://assets/righthip.stl"/>
      </geometry>
      <material name="righthip_6_material">
        <color rgba="0.25 0.25 0.25 1"/>
      </material>
    </visual>
    <collision>
      <origin xyz="-0.180368 -0.005 -0.21218" rpy="-1.5708 9.66473e-16 -3.31402e-14"/>
      <geometry>
        <mesh filename="package://assets/righthip.stl"/>
      </geometry>
    </collision>
    <!-- Part idler_17 -->
    <visual>
      <origin xyz="-0.04286 0.199212 0.00448461" rpy="1.5708 -1.5708 0"/>
      <geometry>
        <mesh filename="package://assets/idler.stl"/>
      </geometry>
      <material name="idler_17_material">
        <color rgba="0.25 0.25 0.25 1"/>
      </material>
    </visual>
    <collision>
      <origin xyz="-0.04286 0.199212 0.00448461" rpy="1.5708 -1.5708 0"/>
      <geometry>
        <mesh filename="package://assets/idler.stl"/>
      </geometry>
    </collision>
    <!-- Part e07_mg996r_17 -->
    <visual>
      <origin xyz="-0.053 0.005 0.0249" rpy="-1.5708 -1.5708 0"/>
      <geometry>
        <mesh filename="package://assets/e07_mg996r.stl"/>
      </geometry>
      <material name="e07_mg996r_17_material">
        <color rgba="0.25 0.25 0.25 1"/>
      </material>
    </visual>
    <collision>
      <origin xyz="-0.053 0.005 0.0249" rpy="-1.5708 -1.5708 0"/>
      <geometry>
        <mesh filename="package://assets/e07_mg996r.stl"/>
      </geometry>
    </collision>
    <!-- Part servo_horns_17 -->
    <visual>
      <origin xyz="-0.053 0.02225 0.0149" rpy="3.14159 -1.5708 0"/>
      <geometry>
        <mesh filename="package://assets/servo_horns.stl"/>
      </geometry>
      <material name="servo_horns_17_material">
        <color rgba="0.25 0.25 0.25 1"/>
      </material>
    </visual>
    <collision>
      <origin xyz="-0.053 0.02225 0.0149" rpy="3.14159 -1.5708 0"/>
      <geometry>
        <mesh filename="package://assets/servo_horns.stl"/>
      </geometry>
    </collision>
  </link>
  <!-- Link tibia_6 -->
  <link name="tibia_6">
    <inertial>
      <origin xyz="0.0409873 -4.33681e-18 0.0247148" rpy="0 0 0"/>
      <mass value="0.0352344"/>
      <inertia ixx="2.78079e-05" ixy="-4.4921e-35" ixz="1.87489e-09" iyy="5.15258e-05" iyz="2.03241e-35" izz="2.43045e-05"/>
    </inertial>
    <!-- Part tibia_6 -->
    <visual>
      <origin xyz="-0.258999 -0.005 -0.230075" rpy="-1.5708 -0 3.9443e-31"/>
      <geometry>
        <mesh filename="package://assets/tibia.stl"/>
      </geometry>
      <material name="tibia_6_material">
        <color rgba="0.25 0.25 0.25 1"/>
      </material>
    </visual>
    <collision>
      <origin xyz="-0.258999 -0.005 -0.230075" rpy="-1.5708 -0 3.9443e-31"/>
      <geometry>
        <mesh filename="package://assets/tibia.stl"/>
      </geometry>
    </collision>
  </link>
  <!-- Link rightfemur_6 -->
  <link name="rightfemur_6">
    <inertial>
      <origin xyz="0.00668249 -0.0181489 -0.0256134" rpy="0 0 0"/>
      <mass value="0.0986065"/>
      <inertia ixx="0.000112293" ixy="5.79279e-06" ixz="1.84967e-07" iyy="3.1167e-05" iyz="3.96574e-06" izz="0.000127739"/>
    </inertial>
    <!-- Part rightfemur_6 -->
    <visual>
      <origin xyz="-0.251053 0.52013 -0.0184" rpy="3.14159 1.46799e-13 -1.5708"/>
      <geometry>
        <mesh filename="package://assets/rightfemur.stl"/>
      </geometry>
      <material name="rightfemur_6_material">
        <color rgba="0.25 0.25 0.25 1"/>
      </material>
    </visual>
    <collision>
      <origin xyz="-0.251053 0.52013 -0.0184" rpy="3.14159 1.46799e-13 -1.5708"/>
      <geometry>
        <mesh filename="package://assets/rightfemur.stl"/>
      </geometry>
    </collision>
    <!-- Part idler_18 -->
    <visual>
      <origin xyz="-0.0104154 0.01014 0.175812" rpy="-3.14159 -1.7053e-13 -5.12784e-14"/>
      <geometry>
        <mesh filename="package://assets/idler.stl"/>
      </geometry>
      <material name="idler_18_material">
        <color rgba="0.25 0.25 0.25 1"/>
      </material>
    </visual>
    <collision>
      <origin xyz="-0.0104154 0.01014 0.175812" rpy="-3.14159 -1.7053e-13 -5.12784e-14"/>
      <geometry>
        <mesh filename="package://assets/idler.stl"/>
      </geometry>
    </collision>
    <!-- Part e07_mg996r_18 -->
    <visual>
      <origin xyz="0.01 2.02616e-15 -0.0184" rpy="1.46855e-13 6.9611e-14 7.81181e-14"/>
      <geometry>
        <mesh filename="package://assets/e07_mg996r.stl"/>
      </geometry>
      <material name="e07_mg996r_18_material">
        <color rgba="0.25 0.25 0.25 1"/>
      </material>
    </visual>
    <collision>
      <origin xyz="0.01 2.02616e-15 -0.0184" rpy="1.46855e-13 6.9611e-14 7.81181e-14"/>
      <geometry>
        <mesh filename="package://assets/e07_mg996r.stl"/>
      </geometry>
    </collision>
    <!-- Part servo_horns_18 -->
    <visual>
      <origin xyz="5.55112e-17 0 -0.00115" rpy="-1.5708 -0 0"/>
      <geometry>
        <mesh filename="package://assets/servo_horns.stl"/>
      </geometry>
      <material name="servo_horns_18_material">
        <color rgba="0.25 0.25 0.25 1"/>
      </material>
    </visual>
    <collision>
      <origin xyz="5.55112e-17 0 -0.00115" rpy="-1.5708 -0 0"/>
      <geometry>
        <mesh filename="package://assets/servo_horns.stl"/>
      </geometry>
    </collision>
  </link>
  <!-- Joint from tibia_6 to rightfemur_6 -->
  <joint name="femur_l3" type="revolute">
    <origin xyz="0.085 -2.80678e-15 1.76248e-15" rpy="3.14159 1.4988e-15 -2.53073"/>
    <parent link="tibia_6"/>
    <child link="rightfemur_6"/>
    <axis xyz="0 0 1"/>
    <limit effort="10" velocity="6" lower="-0.959931" upper="1.22173"/>
    <joint_properties friction="0.5"/>
  </joint>
  <!-- Joint from righthip_6 to tibia_6 -->
  <joint name="tibia_l3" type="revolute">
    <origin xyz="-0.053 0.0234 0.0149" rpy="-1.5708 7.74969e-17 3.14159"/>
    <parent link="righthip_6"/>
    <child link="tibia_6"/>
    <axis xyz="0 0 1"/>
    <limit effort="10" velocity="6" lower="0" upper="1.22173"/>
    <joint_properties friction="0.5"/>
  </joint>
  <!-- Joint from lowerbody to righthip_6 -->
  <joint name="hip_l3" type="revolute">
    <origin xyz="-0.125258 0.0663725 0.0319385" rpy="3.14159 3.08664e-15 -0.436332"/>
    <parent link="lowerbody"/>
    <child link="righthip_6"/>
    <axis xyz="0 0 1"/>
    <limit effort="10" velocity="6" lower="-0.523599" upper="0.523599"/>
    <joint_properties friction="0.5"/>
  </joint>
</robot>
